[2020-06-25 12:04:51,821] INFO run_with_reloader autoreload Watching for file changes with StatReloader
[2020-06-25 12:06:46,707] INFO login login  JACKEY LOGIN
[2020-06-25 12:07:07,952] INFO login login  JACKEY LOGIN
[2020-06-25 12:07:08,116] ERROR log_response log Internal Server Error: /home/
Traceback (most recent call last):
  File "C:\Python3\lib\site-packages\django\core\handlers\exception.py", line 34, in inner
    response = get_response(request)
  File "C:\Python3\lib\site-packages\django\core\handlers\base.py", line 115, in _get_response
    response = self.process_exception_by_middleware(e, request)
  File "C:\Python3\lib\site-packages\django\core\handlers\base.py", line 113, in _get_response
    response = wrapped_callback(request, *callback_args, **callback_kwargs)
  File "C:\Python3\lib\site-packages\django\contrib\auth\decorators.py", line 21, in _wrapped_view
    return view_func(request, *args, **kwargs)
  File "G:\ZED\qauto\autotest\views\home.py", line 103, in home
    os.mkdir(parent_folder)
FileNotFoundError: [WinError 3] 系统找不到指定的路径。: 'G:\\ZED\\qauto\\autotest\\testersinfo\\3ec83be64610f0830a2ebb670072f65f'
[2020-06-25 12:07:08,116] ERROR log_response log Internal Server Error: /home/
Traceback (most recent call last):
  File "C:\Python3\lib\site-packages\django\core\handlers\exception.py", line 34, in inner
    response = get_response(request)
  File "C:\Python3\lib\site-packages\django\core\handlers\base.py", line 115, in _get_response
    response = self.process_exception_by_middleware(e, request)
  File "C:\Python3\lib\site-packages\django\core\handlers\base.py", line 113, in _get_response
    response = wrapped_callback(request, *callback_args, **callback_kwargs)
  File "C:\Python3\lib\site-packages\django\contrib\auth\decorators.py", line 21, in _wrapped_view
    return view_func(request, *args, **kwargs)
  File "G:\ZED\qauto\autotest\views\home.py", line 103, in home
    os.mkdir(parent_folder)
FileNotFoundError: [WinError 3] 系统找不到指定的路径。: 'G:\\ZED\\qauto\\autotest\\testersinfo\\3ec83be64610f0830a2ebb670072f65f'
[2020-06-25 12:07:08,265] WARNING log_response log Not Found: /favicon.ico
[2020-06-25 12:09:10,770] INFO trigger_reload autoreload G:\ZED\qauto\autotest\views\automation\automation.py changed, reloading.
[2020-06-25 12:10:18,678] INFO run_with_reloader autoreload Watching for file changes with StatReloader
[2020-06-25 12:10:27,317] INFO run_with_reloader autoreload Watching for file changes with StatReloader
[2020-06-25 12:10:41,969] INFO trigger_reload autoreload G:\ZED\qauto\autotest\views\automation\automation.py changed, reloading.
[2020-06-25 12:10:42,701] INFO run_with_reloader autoreload Watching for file changes with StatReloader
[2020-06-25 12:11:54,330] INFO run_with_reloader autoreload Watching for file changes with StatReloader
[2020-06-25 12:12:50,822] INFO run_with_reloader autoreload Watching for file changes with StatReloader
[2020-06-25 12:14:20,053] INFO trigger_reload autoreload G:\ZED\qauto\autotest\views\automation\automation.py changed, reloading.
[2020-06-25 12:14:56,641] INFO run_with_reloader autoreload Watching for file changes with StatReloader
[2020-06-25 12:15:35,559] INFO run_with_reloader autoreload Watching for file changes with StatReloader
[2020-06-25 12:17:01,518] WARNING log_response log Not Found: /autotests/
[2020-06-25 12:17:01,602] WARNING log_response log Not Found: /favicon.ico
[2020-06-25 12:17:24,112] INFO login login  JACKEY LOGIN
[2020-06-25 12:17:38,551] INFO login login  JACKEY LOGIN
[2020-06-25 12:23:52,722] INFO trigger_reload autoreload G:\ZED\qauto\autotest\views\api\api.py changed, reloading.
[2020-06-25 12:23:53,484] INFO run_with_reloader autoreload Watching for file changes with StatReloader
[2020-06-25 12:24:41,523] INFO trigger_reload autoreload G:\ZED\qauto\autotest\views\api\api.py changed, reloading.
[2020-06-25 12:24:42,264] INFO run_with_reloader autoreload Watching for file changes with StatReloader
[2020-06-25 12:24:44,713] ERROR log_response log Internal Server Error: /api/request/
Traceback (most recent call last):
  File "C:\Python3\lib\site-packages\django\core\handlers\exception.py", line 34, in inner
    response = get_response(request)
  File "C:\Python3\lib\site-packages\django\core\handlers\base.py", line 115, in _get_response
    response = self.process_exception_by_middleware(e, request)
  File "C:\Python3\lib\site-packages\django\core\handlers\base.py", line 113, in _get_response
    response = wrapped_callback(request, *callback_args, **callback_kwargs)
  File "C:\Python3\lib\site-packages\django\contrib\auth\decorators.py", line 21, in _wrapped_view
    return view_func(request, *args, **kwargs)
  File "G:\ZED\qauto\autotest\views\api\api.py", line 198, in request
    return JsonResponse(result, safe=False)
  File "C:\Python3\lib\site-packages\django\http\response.py", line 587, in __init__
    data = json.dumps(data, cls=encoder, **json_dumps_params)
  File "C:\Python3\lib\json\__init__.py", line 238, in dumps
    **kw).encode(obj)
  File "C:\Python3\lib\json\encoder.py", line 199, in encode
    chunks = self.iterencode(o, _one_shot=True)
  File "C:\Python3\lib\json\encoder.py", line 257, in iterencode
    return _iterencode(o, 0)
  File "C:\Python3\lib\site-packages\django\core\serializers\json.py", line 104, in default
    return super().default(o)
  File "C:\Python3\lib\json\encoder.py", line 179, in default
    raise TypeError(f'Object of type {o.__class__.__name__} '
TypeError: Object of type bytes is not JSON serializable
[2020-06-25 12:24:44,713] ERROR log_response log Internal Server Error: /api/request/
Traceback (most recent call last):
  File "C:\Python3\lib\site-packages\django\core\handlers\exception.py", line 34, in inner
    response = get_response(request)
  File "C:\Python3\lib\site-packages\django\core\handlers\base.py", line 115, in _get_response
    response = self.process_exception_by_middleware(e, request)
  File "C:\Python3\lib\site-packages\django\core\handlers\base.py", line 113, in _get_response
    response = wrapped_callback(request, *callback_args, **callback_kwargs)
  File "C:\Python3\lib\site-packages\django\contrib\auth\decorators.py", line 21, in _wrapped_view
    return view_func(request, *args, **kwargs)
  File "G:\ZED\qauto\autotest\views\api\api.py", line 198, in request
    return JsonResponse(result, safe=False)
  File "C:\Python3\lib\site-packages\django\http\response.py", line 587, in __init__
    data = json.dumps(data, cls=encoder, **json_dumps_params)
  File "C:\Python3\lib\json\__init__.py", line 238, in dumps
    **kw).encode(obj)
  File "C:\Python3\lib\json\encoder.py", line 199, in encode
    chunks = self.iterencode(o, _one_shot=True)
  File "C:\Python3\lib\json\encoder.py", line 257, in iterencode
    return _iterencode(o, 0)
  File "C:\Python3\lib\site-packages\django\core\serializers\json.py", line 104, in default
    return super().default(o)
  File "C:\Python3\lib\json\encoder.py", line 179, in default
    raise TypeError(f'Object of type {o.__class__.__name__} '
TypeError: Object of type bytes is not JSON serializable
[2020-06-25 12:24:49,810] ERROR log_response log Internal Server Error: /api/request/
Traceback (most recent call last):
  File "C:\Python3\lib\site-packages\django\core\handlers\exception.py", line 34, in inner
    response = get_response(request)
  File "C:\Python3\lib\site-packages\django\core\handlers\base.py", line 115, in _get_response
    response = self.process_exception_by_middleware(e, request)
  File "C:\Python3\lib\site-packages\django\core\handlers\base.py", line 113, in _get_response
    response = wrapped_callback(request, *callback_args, **callback_kwargs)
  File "C:\Python3\lib\site-packages\django\contrib\auth\decorators.py", line 21, in _wrapped_view
    return view_func(request, *args, **kwargs)
  File "G:\ZED\qauto\autotest\views\api\api.py", line 198, in request
    return JsonResponse(result, safe=False)
  File "C:\Python3\lib\site-packages\django\http\response.py", line 587, in __init__
    data = json.dumps(data, cls=encoder, **json_dumps_params)
  File "C:\Python3\lib\json\__init__.py", line 238, in dumps
    **kw).encode(obj)
  File "C:\Python3\lib\json\encoder.py", line 199, in encode
    chunks = self.iterencode(o, _one_shot=True)
  File "C:\Python3\lib\json\encoder.py", line 257, in iterencode
    return _iterencode(o, 0)
  File "C:\Python3\lib\site-packages\django\core\serializers\json.py", line 104, in default
    return super().default(o)
  File "C:\Python3\lib\json\encoder.py", line 179, in default
    raise TypeError(f'Object of type {o.__class__.__name__} '
TypeError: Object of type bytes is not JSON serializable
[2020-06-25 12:24:49,810] ERROR log_response log Internal Server Error: /api/request/
Traceback (most recent call last):
  File "C:\Python3\lib\site-packages\django\core\handlers\exception.py", line 34, in inner
    response = get_response(request)
  File "C:\Python3\lib\site-packages\django\core\handlers\base.py", line 115, in _get_response
    response = self.process_exception_by_middleware(e, request)
  File "C:\Python3\lib\site-packages\django\core\handlers\base.py", line 113, in _get_response
    response = wrapped_callback(request, *callback_args, **callback_kwargs)
  File "C:\Python3\lib\site-packages\django\contrib\auth\decorators.py", line 21, in _wrapped_view
    return view_func(request, *args, **kwargs)
  File "G:\ZED\qauto\autotest\views\api\api.py", line 198, in request
    return JsonResponse(result, safe=False)
  File "C:\Python3\lib\site-packages\django\http\response.py", line 587, in __init__
    data = json.dumps(data, cls=encoder, **json_dumps_params)
  File "C:\Python3\lib\json\__init__.py", line 238, in dumps
    **kw).encode(obj)
  File "C:\Python3\lib\json\encoder.py", line 199, in encode
    chunks = self.iterencode(o, _one_shot=True)
  File "C:\Python3\lib\json\encoder.py", line 257, in iterencode
    return _iterencode(o, 0)
  File "C:\Python3\lib\site-packages\django\core\serializers\json.py", line 104, in default
    return super().default(o)
  File "C:\Python3\lib\json\encoder.py", line 179, in default
    raise TypeError(f'Object of type {o.__class__.__name__} '
TypeError: Object of type bytes is not JSON serializable
[2020-06-25 12:25:02,956] INFO trigger_reload autoreload G:\ZED\qauto\autotest\views\api\api.py changed, reloading.
[2020-06-25 12:25:03,689] INFO run_with_reloader autoreload Watching for file changes with StatReloader
[2020-06-25 12:25:32,667] INFO trigger_reload autoreload G:\ZED\qauto\autotest\views\api\api.py changed, reloading.
[2020-06-25 12:25:33,416] INFO run_with_reloader autoreload Watching for file changes with StatReloader
[2020-06-25 12:50:04,463] INFO trigger_reload autoreload G:\ZED\qauto\autotest\views\api\api.py changed, reloading.
[2020-06-25 12:50:05,236] INFO run_with_reloader autoreload Watching for file changes with StatReloader
[2020-06-25 12:50:09,598] ERROR log_response log Internal Server Error: /api/request/
Traceback (most recent call last):
  File "C:\Python3\lib\site-packages\django\core\handlers\exception.py", line 34, in inner
    response = get_response(request)
  File "C:\Python3\lib\site-packages\django\core\handlers\base.py", line 115, in _get_response
    response = self.process_exception_by_middleware(e, request)
  File "C:\Python3\lib\site-packages\django\core\handlers\base.py", line 113, in _get_response
    response = wrapped_callback(request, *callback_args, **callback_kwargs)
  File "C:\Python3\lib\site-packages\django\contrib\auth\decorators.py", line 21, in _wrapped_view
    return view_func(request, *args, **kwargs)
  File "G:\ZED\qauto\autotest\views\api\api.py", line 198, in request
    return JsonResponse(result, safe=False)
  File "C:\Python3\lib\site-packages\django\http\response.py", line 587, in __init__
    data = json.dumps(data, cls=encoder, **json_dumps_params)
  File "C:\Python3\lib\json\__init__.py", line 238, in dumps
    **kw).encode(obj)
  File "C:\Python3\lib\json\encoder.py", line 199, in encode
    chunks = self.iterencode(o, _one_shot=True)
  File "C:\Python3\lib\json\encoder.py", line 257, in iterencode
    return _iterencode(o, 0)
  File "C:\Python3\lib\site-packages\django\core\serializers\json.py", line 104, in default
    return super().default(o)
  File "C:\Python3\lib\json\encoder.py", line 179, in default
    raise TypeError(f'Object of type {o.__class__.__name__} '
TypeError: Object of type bytes is not JSON serializable
[2020-06-25 12:50:09,598] ERROR log_response log Internal Server Error: /api/request/
Traceback (most recent call last):
  File "C:\Python3\lib\site-packages\django\core\handlers\exception.py", line 34, in inner
    response = get_response(request)
  File "C:\Python3\lib\site-packages\django\core\handlers\base.py", line 115, in _get_response
    response = self.process_exception_by_middleware(e, request)
  File "C:\Python3\lib\site-packages\django\core\handlers\base.py", line 113, in _get_response
    response = wrapped_callback(request, *callback_args, **callback_kwargs)
  File "C:\Python3\lib\site-packages\django\contrib\auth\decorators.py", line 21, in _wrapped_view
    return view_func(request, *args, **kwargs)
  File "G:\ZED\qauto\autotest\views\api\api.py", line 198, in request
    return JsonResponse(result, safe=False)
  File "C:\Python3\lib\site-packages\django\http\response.py", line 587, in __init__
    data = json.dumps(data, cls=encoder, **json_dumps_params)
  File "C:\Python3\lib\json\__init__.py", line 238, in dumps
    **kw).encode(obj)
  File "C:\Python3\lib\json\encoder.py", line 199, in encode
    chunks = self.iterencode(o, _one_shot=True)
  File "C:\Python3\lib\json\encoder.py", line 257, in iterencode
    return _iterencode(o, 0)
  File "C:\Python3\lib\site-packages\django\core\serializers\json.py", line 104, in default
    return super().default(o)
  File "C:\Python3\lib\json\encoder.py", line 179, in default
    raise TypeError(f'Object of type {o.__class__.__name__} '
TypeError: Object of type bytes is not JSON serializable
[2020-06-25 12:50:34,216] INFO trigger_reload autoreload G:\ZED\qauto\autotest\views\api\api.py changed, reloading.
[2020-06-25 12:50:34,972] INFO run_with_reloader autoreload Watching for file changes with StatReloader
[2020-06-25 13:08:26,445] INFO trigger_reload autoreload G:\ZED\qauto\autotest\views\api\api.py changed, reloading.
[2020-06-25 13:08:27,190] INFO run_with_reloader autoreload Watching for file changes with StatReloader
[2020-06-25 14:12:40,698] INFO trigger_reload autoreload G:\ZED\qauto\autotest\views\api\api.py changed, reloading.
[2020-06-25 14:12:41,420] INFO run_with_reloader autoreload Watching for file changes with StatReloader
[2020-06-25 14:12:47,742] INFO trigger_reload autoreload G:\ZED\qauto\autotest\views\api\api.py changed, reloading.
[2020-06-25 14:12:48,499] INFO run_with_reloader autoreload Watching for file changes with StatReloader
[2020-06-25 14:16:01,376] INFO trigger_reload autoreload G:\ZED\qauto\autotest\views\api\api.py changed, reloading.
[2020-06-25 14:16:02,130] INFO run_with_reloader autoreload Watching for file changes with StatReloader
[2020-06-25 14:16:04,801] ERROR log_response log Internal Server Error: /api/request/
Traceback (most recent call last):
  File "C:\Python3\lib\site-packages\django\core\handlers\exception.py", line 34, in inner
    response = get_response(request)
  File "C:\Python3\lib\site-packages\django\core\handlers\base.py", line 115, in _get_response
    response = self.process_exception_by_middleware(e, request)
  File "C:\Python3\lib\site-packages\django\core\handlers\base.py", line 113, in _get_response
    response = wrapped_callback(request, *callback_args, **callback_kwargs)
  File "C:\Python3\lib\site-packages\django\contrib\auth\decorators.py", line 21, in _wrapped_view
    return view_func(request, *args, **kwargs)
  File "G:\ZED\qauto\autotest\views\api\api.py", line 199, in request
    print(result)
UnicodeEncodeError: 'gbk' codec can't encode character '\xe7' in position 504: illegal multibyte sequence
[2020-06-25 14:16:04,801] ERROR log_response log Internal Server Error: /api/request/
Traceback (most recent call last):
  File "C:\Python3\lib\site-packages\django\core\handlers\exception.py", line 34, in inner
    response = get_response(request)
  File "C:\Python3\lib\site-packages\django\core\handlers\base.py", line 115, in _get_response
    response = self.process_exception_by_middleware(e, request)
  File "C:\Python3\lib\site-packages\django\core\handlers\base.py", line 113, in _get_response
    response = wrapped_callback(request, *callback_args, **callback_kwargs)
  File "C:\Python3\lib\site-packages\django\contrib\auth\decorators.py", line 21, in _wrapped_view
    return view_func(request, *args, **kwargs)
  File "G:\ZED\qauto\autotest\views\api\api.py", line 199, in request
    print(result)
UnicodeEncodeError: 'gbk' codec can't encode character '\xe7' in position 504: illegal multibyte sequence
[2020-06-25 14:16:22,790] INFO trigger_reload autoreload G:\ZED\qauto\autotest\views\api\api.py changed, reloading.
[2020-06-25 14:16:23,537] INFO run_with_reloader autoreload Watching for file changes with StatReloader
[2020-06-25 14:16:24,191] ERROR log_response log Internal Server Error: /api/request/
Traceback (most recent call last):
  File "C:\Python3\lib\site-packages\django\core\handlers\exception.py", line 34, in inner
    response = get_response(request)
  File "C:\Python3\lib\site-packages\django\core\handlers\base.py", line 115, in _get_response
    response = self.process_exception_by_middleware(e, request)
  File "C:\Python3\lib\site-packages\django\core\handlers\base.py", line 113, in _get_response
    response = wrapped_callback(request, *callback_args, **callback_kwargs)
  File "C:\Python3\lib\site-packages\django\contrib\auth\decorators.py", line 21, in _wrapped_view
    return view_func(request, *args, **kwargs)
  File "G:\ZED\qauto\autotest\views\api\api.py", line 199, in request
    print(result)
UnicodeEncodeError: 'gbk' codec can't encode character '\xe7' in position 483: illegal multibyte sequence
[2020-06-25 14:16:24,191] ERROR log_response log Internal Server Error: /api/request/
Traceback (most recent call last):
  File "C:\Python3\lib\site-packages\django\core\handlers\exception.py", line 34, in inner
    response = get_response(request)
  File "C:\Python3\lib\site-packages\django\core\handlers\base.py", line 115, in _get_response
    response = self.process_exception_by_middleware(e, request)
  File "C:\Python3\lib\site-packages\django\core\handlers\base.py", line 113, in _get_response
    response = wrapped_callback(request, *callback_args, **callback_kwargs)
  File "C:\Python3\lib\site-packages\django\contrib\auth\decorators.py", line 21, in _wrapped_view
    return view_func(request, *args, **kwargs)
  File "G:\ZED\qauto\autotest\views\api\api.py", line 199, in request
    print(result)
UnicodeEncodeError: 'gbk' codec can't encode character '\xe7' in position 483: illegal multibyte sequence
[2020-06-25 14:16:42,011] ERROR log_response log Internal Server Error: /api/request/
Traceback (most recent call last):
  File "C:\Python3\lib\site-packages\django\core\handlers\exception.py", line 34, in inner
    response = get_response(request)
  File "C:\Python3\lib\site-packages\django\core\handlers\base.py", line 115, in _get_response
    response = self.process_exception_by_middleware(e, request)
  File "C:\Python3\lib\site-packages\django\core\handlers\base.py", line 113, in _get_response
    response = wrapped_callback(request, *callback_args, **callback_kwargs)
  File "C:\Python3\lib\site-packages\django\contrib\auth\decorators.py", line 21, in _wrapped_view
    return view_func(request, *args, **kwargs)
  File "G:\ZED\qauto\autotest\views\api\api.py", line 199, in request
    print(result)
UnicodeEncodeError: 'gbk' codec can't encode character '\xa1' in position 9942: illegal multibyte sequence
[2020-06-25 14:16:42,011] ERROR log_response log Internal Server Error: /api/request/
Traceback (most recent call last):
  File "C:\Python3\lib\site-packages\django\core\handlers\exception.py", line 34, in inner
    response = get_response(request)
  File "C:\Python3\lib\site-packages\django\core\handlers\base.py", line 115, in _get_response
    response = self.process_exception_by_middleware(e, request)
  File "C:\Python3\lib\site-packages\django\core\handlers\base.py", line 113, in _get_response
    response = wrapped_callback(request, *callback_args, **callback_kwargs)
  File "C:\Python3\lib\site-packages\django\contrib\auth\decorators.py", line 21, in _wrapped_view
    return view_func(request, *args, **kwargs)
  File "G:\ZED\qauto\autotest\views\api\api.py", line 199, in request
    print(result)
UnicodeEncodeError: 'gbk' codec can't encode character '\xa1' in position 9942: illegal multibyte sequence
[2020-06-25 14:16:48,871] ERROR log_response log Internal Server Error: /api/request/
Traceback (most recent call last):
  File "C:\Python3\lib\site-packages\django\core\handlers\exception.py", line 34, in inner
    response = get_response(request)
  File "C:\Python3\lib\site-packages\django\core\handlers\base.py", line 115, in _get_response
    response = self.process_exception_by_middleware(e, request)
  File "C:\Python3\lib\site-packages\django\core\handlers\base.py", line 113, in _get_response
    response = wrapped_callback(request, *callback_args, **callback_kwargs)
  File "C:\Python3\lib\site-packages\django\contrib\auth\decorators.py", line 21, in _wrapped_view
    return view_func(request, *args, **kwargs)
  File "G:\ZED\qauto\autotest\views\api\api.py", line 199, in request
    print(result)
UnicodeEncodeError: 'gbk' codec can't encode character '\xa1' in position 9942: illegal multibyte sequence
[2020-06-25 14:16:48,871] ERROR log_response log Internal Server Error: /api/request/
Traceback (most recent call last):
  File "C:\Python3\lib\site-packages\django\core\handlers\exception.py", line 34, in inner
    response = get_response(request)
  File "C:\Python3\lib\site-packages\django\core\handlers\base.py", line 115, in _get_response
    response = self.process_exception_by_middleware(e, request)
  File "C:\Python3\lib\site-packages\django\core\handlers\base.py", line 113, in _get_response
    response = wrapped_callback(request, *callback_args, **callback_kwargs)
  File "C:\Python3\lib\site-packages\django\contrib\auth\decorators.py", line 21, in _wrapped_view
    return view_func(request, *args, **kwargs)
  File "G:\ZED\qauto\autotest\views\api\api.py", line 199, in request
    print(result)
UnicodeEncodeError: 'gbk' codec can't encode character '\xa1' in position 9942: illegal multibyte sequence
[2020-06-25 14:17:05,466] INFO trigger_reload autoreload G:\ZED\qauto\autotest\views\api\api.py changed, reloading.
[2020-06-25 14:17:06,197] INFO run_with_reloader autoreload Watching for file changes with StatReloader
[2020-06-25 14:17:26,763] INFO trigger_reload autoreload G:\ZED\qauto\autotest\views\api\api.py changed, reloading.
[2020-06-25 14:17:27,508] INFO run_with_reloader autoreload Watching for file changes with StatReloader
[2020-06-25 14:19:36,170] INFO trigger_reload autoreload G:\ZED\qauto\autotest\views\api\api.py changed, reloading.
[2020-06-25 14:19:36,934] INFO run_with_reloader autoreload Watching for file changes with StatReloader
[2020-06-25 14:20:10,654] INFO trigger_reload autoreload G:\ZED\qauto\autotest\views\api\api.py changed, reloading.
[2020-06-25 14:20:11,396] INFO run_with_reloader autoreload Watching for file changes with StatReloader
[2020-06-25 14:20:17,691] INFO trigger_reload autoreload G:\ZED\qauto\autotest\views\api\api.py changed, reloading.
[2020-06-25 14:20:18,440] INFO run_with_reloader autoreload Watching for file changes with StatReloader
[2020-06-25 14:20:55,896] INFO trigger_reload autoreload G:\ZED\qauto\autotest\views\api\api.py changed, reloading.
[2020-06-25 14:20:56,630] INFO run_with_reloader autoreload Watching for file changes with StatReloader
[2020-06-25 14:21:00,602] INFO trigger_reload autoreload G:\ZED\qauto\autotest\views\api\api.py changed, reloading.
[2020-06-25 14:21:01,337] INFO run_with_reloader autoreload Watching for file changes with StatReloader
[2020-06-25 14:21:10,012] INFO trigger_reload autoreload G:\ZED\qauto\autotest\views\api\api.py changed, reloading.
[2020-06-25 14:21:10,735] INFO run_with_reloader autoreload Watching for file changes with StatReloader
[2020-06-25 14:22:11,930] INFO trigger_reload autoreload G:\ZED\qauto\autotest\views\api\api.py changed, reloading.
[2020-06-25 14:22:12,681] INFO run_with_reloader autoreload Watching for file changes with StatReloader
[2020-06-25 14:22:16,400] ERROR log_response log Internal Server Error: /api/request/
Traceback (most recent call last):
  File "C:\Python3\lib\site-packages\django\core\handlers\exception.py", line 34, in inner
    response = get_response(request)
  File "C:\Python3\lib\site-packages\django\core\handlers\base.py", line 115, in _get_response
    response = self.process_exception_by_middleware(e, request)
  File "C:\Python3\lib\site-packages\django\core\handlers\base.py", line 113, in _get_response
    response = wrapped_callback(request, *callback_args, **callback_kwargs)
  File "C:\Python3\lib\site-packages\django\contrib\auth\decorators.py", line 21, in _wrapped_view
    return view_func(request, *args, **kwargs)
  File "G:\ZED\qauto\autotest\views\api\api.py", line 199, in request
    print(result)
UnicodeEncodeError: 'gbk' codec can't encode character '\xa1' in position 9942: illegal multibyte sequence
[2020-06-25 14:22:16,400] ERROR log_response log Internal Server Error: /api/request/
Traceback (most recent call last):
  File "C:\Python3\lib\site-packages\django\core\handlers\exception.py", line 34, in inner
    response = get_response(request)
  File "C:\Python3\lib\site-packages\django\core\handlers\base.py", line 115, in _get_response
    response = self.process_exception_by_middleware(e, request)
  File "C:\Python3\lib\site-packages\django\core\handlers\base.py", line 113, in _get_response
    response = wrapped_callback(request, *callback_args, **callback_kwargs)
  File "C:\Python3\lib\site-packages\django\contrib\auth\decorators.py", line 21, in _wrapped_view
    return view_func(request, *args, **kwargs)
  File "G:\ZED\qauto\autotest\views\api\api.py", line 199, in request
    print(result)
UnicodeEncodeError: 'gbk' codec can't encode character '\xa1' in position 9942: illegal multibyte sequence
[2020-06-25 14:22:39,290] INFO trigger_reload autoreload G:\ZED\qauto\autotest\views\api\api.py changed, reloading.
[2020-06-25 14:22:40,023] INFO run_with_reloader autoreload Watching for file changes with StatReloader
[2020-06-25 15:15:57,408] INFO trigger_reload autoreload G:\ZED\qauto\autotest\views\api\api.py changed, reloading.
[2020-06-25 15:15:58,150] INFO run_with_reloader autoreload Watching for file changes with StatReloader
[2020-06-25 15:30:16,171] INFO login login  JACKEY LOGIN
[2020-06-25 16:19:58,916] INFO trigger_reload autoreload G:\ZED\qauto\autotest\views\api\api.py changed, reloading.
[2020-06-25 16:19:59,676] INFO run_with_reloader autoreload Watching for file changes with StatReloader
[2020-06-25 16:43:33,107] INFO trigger_reload autoreload G:\ZED\qauto\autotest\views\api\api.py changed, reloading.
[2020-06-25 16:43:33,847] INFO run_with_reloader autoreload Watching for file changes with StatReloader
[2020-06-25 16:47:09,696] INFO trigger_reload autoreload G:\ZED\qauto\autotest\views\api\api.py changed, reloading.
[2020-06-25 16:47:10,435] INFO run_with_reloader autoreload Watching for file changes with StatReloader
[2020-06-25 16:49:08,387] INFO trigger_reload autoreload G:\ZED\qauto\autotest\views\api\api.py changed, reloading.
[2020-06-25 16:49:09,126] INFO run_with_reloader autoreload Watching for file changes with StatReloader
[2020-06-25 16:49:29,692] INFO trigger_reload autoreload G:\ZED\qauto\autotest\views\api\api.py changed, reloading.
[2020-06-25 16:49:30,440] INFO run_with_reloader autoreload Watching for file changes with StatReloader
[2020-06-25 16:54:43,909] INFO trigger_reload autoreload G:\ZED\qauto\autotest\views\api\api.py changed, reloading.
[2020-06-25 16:54:44,637] INFO run_with_reloader autoreload Watching for file changes with StatReloader
[2020-06-25 16:56:36,451] INFO trigger_reload autoreload G:\ZED\qauto\autotest\views\api\api.py changed, reloading.
[2020-06-25 16:56:37,189] INFO run_with_reloader autoreload Watching for file changes with StatReloader
[2020-06-25 16:56:41,144] INFO trigger_reload autoreload G:\ZED\qauto\autotest\views\api\api.py changed, reloading.
[2020-06-25 16:56:41,874] INFO run_with_reloader autoreload Watching for file changes with StatReloader
[2020-06-25 17:00:12,476] INFO trigger_reload autoreload G:\ZED\qauto\autotest\views\api\api.py changed, reloading.
[2020-06-25 17:00:13,214] INFO run_with_reloader autoreload Watching for file changes with StatReloader
[2020-06-25 17:03:31,837] INFO trigger_reload autoreload G:\ZED\qauto\autotest\views\api\api.py changed, reloading.
[2020-06-25 17:03:32,588] INFO run_with_reloader autoreload Watching for file changes with StatReloader
[2020-06-25 17:05:10,269] INFO trigger_reload autoreload G:\ZED\qauto\autotest\views\api\api.py changed, reloading.
[2020-06-25 17:05:11,017] INFO run_with_reloader autoreload Watching for file changes with StatReloader
[2020-06-25 17:07:06,425] INFO trigger_reload autoreload G:\ZED\qauto\autotest\views\api\api.py changed, reloading.
[2020-06-25 17:07:07,149] INFO run_with_reloader autoreload Watching for file changes with StatReloader
[2020-06-25 17:07:20,605] INFO trigger_reload autoreload G:\ZED\qauto\autotest\views\api\api.py changed, reloading.
[2020-06-25 17:07:21,359] INFO run_with_reloader autoreload Watching for file changes with StatReloader
[2020-06-25 17:09:05,063] INFO trigger_reload autoreload G:\ZED\qauto\autotest\views\api\api.py changed, reloading.
[2020-06-25 17:09:05,829] INFO run_with_reloader autoreload Watching for file changes with StatReloader
[2020-06-25 17:27:16,026] INFO login login  JACKEY LOGIN
[2020-06-25 21:23:18,344] ERROR log_response log Internal Server Error: /api/request/
Traceback (most recent call last):
  File "C:\Python3\lib\site-packages\django\contrib\sessions\backends\base.py", line 199, in _get_session
    return self._session_cache
AttributeError: 'SessionStore' object has no attribute '_session_cache'

During handling of the above exception, another exception occurred:

Traceback (most recent call last):
  File "C:\Python3\lib\site-packages\django\db\backends\base\base.py", line 220, in ensure_connection
    self.connect()
  File "C:\Python3\lib\site-packages\django\utils\asyncio.py", line 26, in inner
    return func(*args, **kwargs)
  File "C:\Python3\lib\site-packages\django\db\backends\base\base.py", line 197, in connect
    self.connection = self.get_new_connection(conn_params)
  File "C:\Python3\lib\site-packages\django\utils\asyncio.py", line 26, in inner
    return func(*args, **kwargs)
  File "C:\Python3\lib\site-packages\django\db\backends\mysql\base.py", line 233, in get_new_connection
    return Database.connect(**conn_params)
  File "C:\Python3\lib\site-packages\MySQLdb\__init__.py", line 84, in Connect
    return Connection(*args, **kwargs)
  File "C:\Python3\lib\site-packages\MySQLdb\connections.py", line 179, in __init__
    super(Connection, self).__init__(*args, **kwargs2)
MySQLdb._exceptions.OperationalError: (2002, "Can't connect to MySQL server on '127.0.0.1' (10061)")

The above exception was the direct cause of the following exception:

Traceback (most recent call last):
  File "C:\Python3\lib\site-packages\django\core\handlers\exception.py", line 34, in inner
    response = get_response(request)
  File "C:\Python3\lib\site-packages\django\core\handlers\base.py", line 115, in _get_response
    response = self.process_exception_by_middleware(e, request)
  File "C:\Python3\lib\site-packages\django\core\handlers\base.py", line 113, in _get_response
    response = wrapped_callback(request, *callback_args, **callback_kwargs)
  File "C:\Python3\lib\site-packages\django\contrib\auth\decorators.py", line 20, in _wrapped_view
    if test_func(request.user):
  File "C:\Python3\lib\site-packages\django\contrib\auth\decorators.py", line 44, in <lambda>
    lambda u: u.is_authenticated,
  File "C:\Python3\lib\site-packages\django\utils\functional.py", line 224, in inner
    self._setup()
  File "C:\Python3\lib\site-packages\django\utils\functional.py", line 360, in _setup
    self._wrapped = self._setupfunc()
  File "C:\Python3\lib\site-packages\django\contrib\auth\middleware.py", line 24, in <lambda>
    request.user = SimpleLazyObject(lambda: get_user(request))
  File "C:\Python3\lib\site-packages\django\contrib\auth\middleware.py", line 12, in get_user
    request._cached_user = auth.get_user(request)
  File "C:\Python3\lib\site-packages\django\contrib\auth\__init__.py", line 173, in get_user
    user_id = _get_user_session_key(request)
  File "C:\Python3\lib\site-packages\django\contrib\auth\__init__.py", line 58, in _get_user_session_key
    return get_user_model()._meta.pk.to_python(request.session[SESSION_KEY])
  File "C:\Python3\lib\site-packages\django\contrib\sessions\backends\base.py", line 64, in __getitem__
    return self._session[key]
  File "C:\Python3\lib\site-packages\django\contrib\sessions\backends\base.py", line 204, in _get_session
    self._session_cache = self.load()
  File "C:\Python3\lib\site-packages\django\contrib\sessions\backends\db.py", line 43, in load
    s = self._get_session_from_db()
  File "C:\Python3\lib\site-packages\django\contrib\sessions\backends\db.py", line 34, in _get_session_from_db
    expire_date__gt=timezone.now()
  File "C:\Python3\lib\site-packages\django\db\models\manager.py", line 82, in manager_method
    return getattr(self.get_queryset(), name)(*args, **kwargs)
  File "C:\Python3\lib\site-packages\django\db\models\query.py", line 411, in get
    num = len(clone)
  File "C:\Python3\lib\site-packages\django\db\models\query.py", line 258, in __len__
    self._fetch_all()
  File "C:\Python3\lib\site-packages\django\db\models\query.py", line 1261, in _fetch_all
    self._result_cache = list(self._iterable_class(self))
  File "C:\Python3\lib\site-packages\django\db\models\query.py", line 57, in __iter__
    results = compiler.execute_sql(chunked_fetch=self.chunked_fetch, chunk_size=self.chunk_size)
  File "C:\Python3\lib\site-packages\django\db\models\sql\compiler.py", line 1142, in execute_sql
    cursor = self.connection.cursor()
  File "C:\Python3\lib\site-packages\django\utils\asyncio.py", line 26, in inner
    return func(*args, **kwargs)
  File "C:\Python3\lib\site-packages\django\db\backends\base\base.py", line 260, in cursor
    return self._cursor()
  File "C:\Python3\lib\site-packages\django\db\backends\base\base.py", line 236, in _cursor
    self.ensure_connection()
  File "C:\Python3\lib\site-packages\django\utils\asyncio.py", line 26, in inner
    return func(*args, **kwargs)
  File "C:\Python3\lib\site-packages\django\db\backends\base\base.py", line 220, in ensure_connection
    self.connect()
  File "C:\Python3\lib\site-packages\django\db\utils.py", line 90, in __exit__
    raise dj_exc_value.with_traceback(traceback) from exc_value
  File "C:\Python3\lib\site-packages\django\db\backends\base\base.py", line 220, in ensure_connection
    self.connect()
  File "C:\Python3\lib\site-packages\django\utils\asyncio.py", line 26, in inner
    return func(*args, **kwargs)
  File "C:\Python3\lib\site-packages\django\db\backends\base\base.py", line 197, in connect
    self.connection = self.get_new_connection(conn_params)
  File "C:\Python3\lib\site-packages\django\utils\asyncio.py", line 26, in inner
    return func(*args, **kwargs)
  File "C:\Python3\lib\site-packages\django\db\backends\mysql\base.py", line 233, in get_new_connection
    return Database.connect(**conn_params)
  File "C:\Python3\lib\site-packages\MySQLdb\__init__.py", line 84, in Connect
    return Connection(*args, **kwargs)
  File "C:\Python3\lib\site-packages\MySQLdb\connections.py", line 179, in __init__
    super(Connection, self).__init__(*args, **kwargs2)
django.db.utils.OperationalError: (2002, "Can't connect to MySQL server on '127.0.0.1' (10061)")
[2020-06-25 21:23:18,344] ERROR log_response log Internal Server Error: /api/request/
Traceback (most recent call last):
  File "C:\Python3\lib\site-packages\django\contrib\sessions\backends\base.py", line 199, in _get_session
    return self._session_cache
AttributeError: 'SessionStore' object has no attribute '_session_cache'

During handling of the above exception, another exception occurred:

Traceback (most recent call last):
  File "C:\Python3\lib\site-packages\django\db\backends\base\base.py", line 220, in ensure_connection
    self.connect()
  File "C:\Python3\lib\site-packages\django\utils\asyncio.py", line 26, in inner
    return func(*args, **kwargs)
  File "C:\Python3\lib\site-packages\django\db\backends\base\base.py", line 197, in connect
    self.connection = self.get_new_connection(conn_params)
  File "C:\Python3\lib\site-packages\django\utils\asyncio.py", line 26, in inner
    return func(*args, **kwargs)
  File "C:\Python3\lib\site-packages\django\db\backends\mysql\base.py", line 233, in get_new_connection
    return Database.connect(**conn_params)
  File "C:\Python3\lib\site-packages\MySQLdb\__init__.py", line 84, in Connect
    return Connection(*args, **kwargs)
  File "C:\Python3\lib\site-packages\MySQLdb\connections.py", line 179, in __init__
    super(Connection, self).__init__(*args, **kwargs2)
MySQLdb._exceptions.OperationalError: (2002, "Can't connect to MySQL server on '127.0.0.1' (10061)")

The above exception was the direct cause of the following exception:

Traceback (most recent call last):
  File "C:\Python3\lib\site-packages\django\core\handlers\exception.py", line 34, in inner
    response = get_response(request)
  File "C:\Python3\lib\site-packages\django\core\handlers\base.py", line 115, in _get_response
    response = self.process_exception_by_middleware(e, request)
  File "C:\Python3\lib\site-packages\django\core\handlers\base.py", line 113, in _get_response
    response = wrapped_callback(request, *callback_args, **callback_kwargs)
  File "C:\Python3\lib\site-packages\django\contrib\auth\decorators.py", line 20, in _wrapped_view
    if test_func(request.user):
  File "C:\Python3\lib\site-packages\django\contrib\auth\decorators.py", line 44, in <lambda>
    lambda u: u.is_authenticated,
  File "C:\Python3\lib\site-packages\django\utils\functional.py", line 224, in inner
    self._setup()
  File "C:\Python3\lib\site-packages\django\utils\functional.py", line 360, in _setup
    self._wrapped = self._setupfunc()
  File "C:\Python3\lib\site-packages\django\contrib\auth\middleware.py", line 24, in <lambda>
    request.user = SimpleLazyObject(lambda: get_user(request))
  File "C:\Python3\lib\site-packages\django\contrib\auth\middleware.py", line 12, in get_user
    request._cached_user = auth.get_user(request)
  File "C:\Python3\lib\site-packages\django\contrib\auth\__init__.py", line 173, in get_user
    user_id = _get_user_session_key(request)
  File "C:\Python3\lib\site-packages\django\contrib\auth\__init__.py", line 58, in _get_user_session_key
    return get_user_model()._meta.pk.to_python(request.session[SESSION_KEY])
  File "C:\Python3\lib\site-packages\django\contrib\sessions\backends\base.py", line 64, in __getitem__
    return self._session[key]
  File "C:\Python3\lib\site-packages\django\contrib\sessions\backends\base.py", line 204, in _get_session
    self._session_cache = self.load()
  File "C:\Python3\lib\site-packages\django\contrib\sessions\backends\db.py", line 43, in load
    s = self._get_session_from_db()
  File "C:\Python3\lib\site-packages\django\contrib\sessions\backends\db.py", line 34, in _get_session_from_db
    expire_date__gt=timezone.now()
  File "C:\Python3\lib\site-packages\django\db\models\manager.py", line 82, in manager_method
    return getattr(self.get_queryset(), name)(*args, **kwargs)
  File "C:\Python3\lib\site-packages\django\db\models\query.py", line 411, in get
    num = len(clone)
  File "C:\Python3\lib\site-packages\django\db\models\query.py", line 258, in __len__
    self._fetch_all()
  File "C:\Python3\lib\site-packages\django\db\models\query.py", line 1261, in _fetch_all
    self._result_cache = list(self._iterable_class(self))
  File "C:\Python3\lib\site-packages\django\db\models\query.py", line 57, in __iter__
    results = compiler.execute_sql(chunked_fetch=self.chunked_fetch, chunk_size=self.chunk_size)
  File "C:\Python3\lib\site-packages\django\db\models\sql\compiler.py", line 1142, in execute_sql
    cursor = self.connection.cursor()
  File "C:\Python3\lib\site-packages\django\utils\asyncio.py", line 26, in inner
    return func(*args, **kwargs)
  File "C:\Python3\lib\site-packages\django\db\backends\base\base.py", line 260, in cursor
    return self._cursor()
  File "C:\Python3\lib\site-packages\django\db\backends\base\base.py", line 236, in _cursor
    self.ensure_connection()
  File "C:\Python3\lib\site-packages\django\utils\asyncio.py", line 26, in inner
    return func(*args, **kwargs)
  File "C:\Python3\lib\site-packages\django\db\backends\base\base.py", line 220, in ensure_connection
    self.connect()
  File "C:\Python3\lib\site-packages\django\db\utils.py", line 90, in __exit__
    raise dj_exc_value.with_traceback(traceback) from exc_value
  File "C:\Python3\lib\site-packages\django\db\backends\base\base.py", line 220, in ensure_connection
    self.connect()
  File "C:\Python3\lib\site-packages\django\utils\asyncio.py", line 26, in inner
    return func(*args, **kwargs)
  File "C:\Python3\lib\site-packages\django\db\backends\base\base.py", line 197, in connect
    self.connection = self.get_new_connection(conn_params)
  File "C:\Python3\lib\site-packages\django\utils\asyncio.py", line 26, in inner
    return func(*args, **kwargs)
  File "C:\Python3\lib\site-packages\django\db\backends\mysql\base.py", line 233, in get_new_connection
    return Database.connect(**conn_params)
  File "C:\Python3\lib\site-packages\MySQLdb\__init__.py", line 84, in Connect
    return Connection(*args, **kwargs)
  File "C:\Python3\lib\site-packages\MySQLdb\connections.py", line 179, in __init__
    super(Connection, self).__init__(*args, **kwargs2)
django.db.utils.OperationalError: (2002, "Can't connect to MySQL server on '127.0.0.1' (10061)")
[2020-06-25 21:23:25,260] INFO run_with_reloader autoreload Watching for file changes with StatReloader
[2020-06-25 21:24:07,773] INFO run_with_reloader autoreload Watching for file changes with StatReloader
[2020-06-25 21:25:12,593] INFO run_with_reloader autoreload Watching for file changes with StatReloader
[2020-06-25 22:05:05,182] INFO run_with_reloader autoreload Watching for file changes with StatReloader
[2020-06-25 22:05:37,463] INFO run_with_reloader autoreload Watching for file changes with StatReloader
[2020-06-25 22:06:27,191] INFO run_with_reloader autoreload Watching for file changes with StatReloader
[2020-06-25 22:06:44,637] INFO run_with_reloader autoreload Watching for file changes with StatReloader
[2020-06-25 22:06:49,673] INFO run_with_reloader autoreload Watching for file changes with StatReloader
[2020-06-25 22:07:20,214] INFO run_with_reloader autoreload Watching for file changes with StatReloader
[2020-06-25 22:08:34,577] INFO trigger_reload autoreload G:\ZED\qauto\qauto\settings.py changed, reloading.
[2020-06-25 22:08:35,348] INFO run_with_reloader autoreload Watching for file changes with StatReloader
[2020-06-25 22:08:55,588] INFO login login  JACKEY LOGIN
[2020-06-25 22:09:05,842] INFO login login  JACKEY LOGIN
[2020-06-25 23:57:57,796] INFO run_with_reloader autoreload Watching for file changes with StatReloader
[2020-06-25 23:58:06,587] INFO trigger_reload autoreload G:\ZED\qauto\qauto\settings.py changed, reloading.
[2020-06-25 23:58:07,380] INFO run_with_reloader autoreload Watching for file changes with StatReloader
[2020-06-25 23:58:25,605] INFO run_with_reloader autoreload Watching for file changes with StatReloader
[2020-06-25 23:59:31,857] INFO run_with_reloader autoreload Watching for file changes with StatReloader
[2020-06-25 23:59:42,821] INFO run_with_reloader autoreload Watching for file changes with StatReloader
